<robot name="self_driving_car">
  <link name="base_link">
    <visual>
      <geometry>
        <box size="0.20 0.10 0.155"/>
      </geometry>
      <material name="white"/>
    </visual>
  </link>
  <joint name="base_to_wheel" type="continuous">
    <parent link="base_link"/>
    <child link="wheel"/>
    <origin xyz="0 0 -0.0775" rpy="0 0 0"/>
    <axis xyz="0 1 0"/>
  </joint>
  <link name="wheel">
    <visual>
      <geometry>
        <cylinder radius="0.025" length="0.05"/>
      </geometry>
      <material name="black"/>
    </visual>
  </link>
</robot>
